<?xml version="1.0" ?>
<!--
    It is discouraged to edit this file. If you wish to make any
    modifications, it is best practice to create your own following
    the specifications found in http://sdformat.org/spec?elem=sdf&ver=1.5 -->

<sdf version="1.5">
    <model name="dede">
        <pose>0.0 0.0 0.0 0.0 0.0 0.0 </pose>
        <link name="base_link">
            <inertial>
                <pose>0.0 0 0.068 0 0 0</pose>
                <inertia>
                    <ixx>0.03815752</ixx>
                    <ixy>0.00009502</ixy>
                    <ixz>-0.00333401</ixz>
                    <iyy>0.03754338</iyy>
                    <iyz>0.00006971</iyz>
                    <izz>0.02037722</izz>
                </inertia>
                <mass>2.93633725</mass>
            </inertial>
            <collision name="base_collision">
                <pose>0.0 0 0.106 0 0 0</pose>
                <geometry>
                    <cylinder>
                        <radius>0.15</radius>
                        <length>0.06</length>
                    </cylinder>
                </geometry>
                <surface>
                    <friction>
                        <ode>
                            <mu>0.5</mu>
                            <mu2>0.5</mu2>
                        </ode>
                    </friction>
                </surface>
            </collision>
            <visual name="base_visual">
                <pose>0 0 0 0 0 0</pose>
                <geometry>
                    <mesh>
                        <uri>model://dede/meshes/base.stl</uri>
                        <scale>1 1 1</scale>
                    </mesh>
                </geometry>
            </visual>
        </link>

        <link name="lidar_link">
            <inertial>
                <pose>0 0 0.163 0 0 0</pose>
                <inertia>
                    <ixx>0.000001</ixx>
                    <ixy>0.000</ixy>
                    <ixz>0.000</ixz>
                    <iyy>0.000001</iyy>
                    <iyz>0.000</iyz>
                    <izz>0.000001</izz>
                </inertia>
                <mass>0.114</mass>
            </inertial>
            <collision name="lidar_collision">
                <pose>-0.0125 0 0.163 0 0 0</pose>
                <geometry>
                    <box>
                        <size>0.097488 0.071778 0.0535</size>
                    </box>
                </geometry>
            </collision>
            <visual name="lidar_visual">
                <pose>0 0 0.0 0 0 0</pose>
                <geometry>
                    <mesh>
                        <uri>model://dede/meshes/lidar.stl</uri>
                        <scale>1 1 1</scale>
                    </mesh>
                </geometry>
            </visual>
            <sensor name="rpi_a1" type="ray">
                <always_on>true</always_on>
                <visualize>false</visualize>
                <pose>0 0 0.18 0 0 0</pose>
                <update_rate>10</update_rate>
                <ray>
                <scan>
                    <horizontal>
                    <samples>360</samples>
                    <resolution>1.0</resolution>
                    <min_angle>0.0</min_angle>
                    <max_angle>6.28</max_angle>
                    </horizontal>
                </scan>
                <range>
                    <min>0.12</min>
                    <max>10.0</max>
                    <resolution>0.015000</resolution>
                </range>
                <noise>
                    <type>gaussian</type>
                    <mean>0.0</mean>
                    <stddev>0.01</stddev>
                </noise>
                </ray>
                <plugin name="dede_laserscan" filename="libgazebo_ros_ray_sensor.so">
                <ros>
                    <remapping>~/out:=scan</remapping>
                </ros>
                <output_type>sensor_msgs/LaserScan</output_type>
                <frame_name>lidar_link</frame_name>
                </plugin>
            </sensor>
        </link>

        <link name="left_wheel_link">
            <inertial>
                <pose>0 0.124 0.038 -1.57 0 0</pose>
                <inertia>
                    <ixx>0.0000645</ixx>
                    <ixy>0.000</ixy>
                    <ixz>0.000</ixz>
                    <iyy>0.0000645</iyy>
                    <iyz>0.000</iyz>
                    <izz>0.0001287</izz>
                </inertia>
                <mass>0.015</mass>
            </inertial>
            <collision name="left_wheel_collision">
                <pose>0 0.124 0.038 -1.57 0 0</pose>
                <geometry>
                    <cylinder>
                        <radius>0.038</radius>
                        <length>0.01</length>
                    </cylinder>
                </geometry>
                <surface>
                    <friction>
                        <ode>
                            <mu>0.9</mu>
                            <mu2>0.9</mu2>
                        </ode>
                    </friction>
                </surface>
            </collision>
            <visual name="left_wheel_visual">
                <pose>0 0.122 0.038 -1.57 0 0</pose>
                <geometry>
                    <mesh>
                        <uri>model://dede/meshes/wheel.stl</uri>
                        <scale>1 1 1</scale>
                    </mesh>
                </geometry>
            </visual>
        </link>

        <link name="right_wheel_link">
            <inertial>
                <pose>0 -0.124 0.038 -1.57 0 0</pose>
                <inertia>
                    <ixx>0.0000645</ixx>
                    <ixy>0.000</ixy>
                    <ixz>0.000</ixz>
                    <iyy>0.0000645</iyy>
                    <iyz>0.000</iyz>
                    <izz>0.0001287</izz>
                </inertia>
                <mass>0.015</mass>
            </inertial>
            <collision name="right_wheel_collision">
                <pose>0 -0.124 0.038 1.57 0 0</pose>
                <geometry>
                    <cylinder>
                        <radius>0.038</radius>
                        <length>0.01</length>
                    </cylinder>
                </geometry>
                <surface>
                    <friction>
                        <ode>
                            <mu>0.9</mu>
                            <mu2>0.9</mu2>
                        </ode>
                    </friction>
                </surface>
            </collision>
            <visual name="right_wheel_visual">
                <pose>0 -0.122 0.038 1.57 0 0</pose>
                <geometry>
                    <mesh>
                        <uri>model://dede/meshes/wheel.stl</uri>
                        <scale>1 1 1</scale>
                    </mesh>
                </geometry>
            </visual>
        </link>

        <link name="invisible_front_caster_link">
            <inertial>
                <pose>0.115 0 0.025 0 0 0</pose>
                <inertia>
                    <ixx>0.000001</ixx>
                    <ixy>0.000</ixy>
                    <ixz>0.000</ixz>
                    <iyy>0.000001</iyy>
                    <iyz>0.000</iyz>
                    <izz>0.000001</izz>
                </inertia>
                <mass>0.01</mass>
            </inertial>
            <collision name='invisible_front_caster_collision'>
                <pose>0.115 0 0.025 0 0 0</pose>
                <geometry>
                    <sphere>
                        <radius>0.025</radius>
                    </sphere>
                </geometry>
                <surface>
                    <friction>
                        <ode>
                            <mu>0.0</mu>
                            <mu2>0.0</mu2>
                        </ode>
                    </friction>
                </surface>
            </collision>
        </link>
        <link name="invisible_back_caster_link">
            <inertial>
                <pose>-0.125 0 0.025 0 0 0</pose>
                <inertia>
                    <ixx>0.000001</ixx>
                    <ixy>0.000</ixy>
                    <ixz>0.000</ixz>
                    <iyy>0.000001</iyy>
                    <iyz>0.000</iyz>
                    <izz>0.000001</izz>
                </inertia>
                <mass>0.01</mass>
            </inertial>
            <collision name='invisible_back_caster_collision'>
                <pose>-0.125 0 0.025 0 0 0</pose>
                <geometry>
                    <sphere>
                        <radius>0.025</radius>
                    </sphere>
                </geometry>
                <surface>
                    <friction>
                        <ode>
                            <mu>0.0</mu>
                            <mu2>0.0</mu2>
                        </ode>
                    </friction>
                </surface>
            </collision>
        </link>

        <joint name="lidar_joint" type="fixed">
            <parent>base_link</parent>
            <child>lidar_link</child>
            <pose>0 0 0.163 0 0 0</pose>
        </joint>
        <joint name="left_wheel_joint" type="revolute">
            <parent>base_link</parent>
            <child>left_wheel_link</child>
            <pose>0 0.124 0.038 -1.57 0 0</pose>
            <axis>
                <xyz>0 0 1</xyz>
            </axis>
            <limit>
                <effort>0.25</effort>
            </limit>
        </joint>
        <joint name="right_wheel_joint" type="revolute">
            <parent>base_link</parent>
            <child>right_wheel_link</child>
            <pose>0 -0.124 0.038 -1.57 0 0</pose>
            <axis>
                <xyz>0 0 1</xyz>
            </axis>
            <limit>
                <effort>0.25</effort>
            </limit>
        </joint>
        <joint name="invisible_front_caster_joint" type="ball">
            <parent>base_link</parent>
            <child>invisible_front_caster_link</child>
            <pose>0.115 0 0.025 0 0 0</pose>
        </joint>
        <joint name="invisible_back_caster_joint" type="ball">
            <parent>base_link</parent>
            <child>invisible_back_caster_link</child>
            <pose>-0.125 0 0.025 0 0 0</pose>
        </joint>

        <plugin name="dede_diff_drive" filename="libgazebo_ros_diff_drive.so">
            <update_rate>50</update_rate>
            <ros>
                <remapping>/tf:=tf</remapping>
            </ros>
            <left_joint>left_wheel_joint</left_joint>
            <right_joint>right_wheel_joint</right_joint>
            <wheel_separation>0.248</wheel_separation>
            <wheel_diameter>0.076</wheel_diameter>
            <max_wheel_torque>0.5</max_wheel_torque>
            <max_wheel_acceleration>2.0</max_wheel_acceleration>
            <command_topic>cmd_vel</command_topic>
            <publish_odom>true</publish_odom>
            <publish_odom_tf>true</publish_odom_tf>
            <publish_wheel_tf>false</publish_wheel_tf>

            <odometry_topic>odom</odometry_topic>
            <odometry_frame>odom</odometry_frame>
            <robot_base_frame>base_link</robot_base_frame>
        </plugin>
        
        <plugin name="dede_joint_state" filename="libgazebo_ros_joint_state_publisher.so">
            <ros>
                <remapping>~/out:=joint_states</remapping>
            </ros>
            <update_rate>50</update_rate>
            <joint_name>left_wheel_joint</joint_name>
            <joint_name>right_wheel_joint</joint_name>
        </plugin>
    </model>
</sdf>