<robot name="dede">
    <material name="grey">
        <color rgba="0.5 0.5 0.5 1.0" />
    </material>

    <link name="base_link">
        <visual>
            <origin xyz="0 0 0" rpy="0 0 0" />
            <geometry>
                <mesh filename="package://dede/models/dede/meshes/base.stl"/>
            </geometry>
            <material name="grey" />
        </visual>
    </link>
    <link name="lidar_link">
        <visual>
            <origin xyz="0 0 -0.136" rpy="0 0 0" />
            <geometry>
                <mesh filename="package://dede/models/dede/meshes/lidar.stl" />
            </geometry>
            <material name="grey" />
        </visual>
    </link>
    <joint name="lidar_joint" type="fixed">
        <parent link="base_link"/>
        <child link="lidar_link"/>
        <origin xyz="0 0 0.136" rpy="0 0 0"/>
    </joint>

    <link name="left_wheel_link">
        <visual>
            <origin xyz="0 0 0" rpy="0 0 0" />
            <geometry>
                <mesh filename="package://dede/models/dede/meshes/wheel.stl" />
            </geometry>
            <material name="grey" />
        </visual>
    </link>
    <joint name="left_wheel_joint" type="continuous">
        <parent link="base_link"/>
        <child link="left_wheel_link"/>
        <origin xyz="0 0.124 0.038" rpy="-1.57 0 0"/>
        <axis xyz="0 0 1"/>
    </joint>

    <link name="right_wheel_link">
        <visual>
            <origin xyz="0 0 0" rpy="0 0 0" />
            <geometry>
                <mesh filename="package://dede/models/dede/meshes/wheel.stl" />
            </geometry>
            <material name="grey" />
        </visual>
    </link>
    <joint name="right_wheel_joint" type="continuous">
        <parent link="base_link"/>
        <child link="right_wheel_link"/>
        <origin xyz="0 -0.124 0.038" rpy="-1.57 0 0"/>
        <axis xyz="0 0 1"/>
    </joint>
</robot>